Workbook

Sheet 2026 Points
A1: Team | B1: Rank | C1: Null | D1: Points
A2: Nick | B2: =rank(D2,D$2:D$10) -> 6 | C2: =countif(E2:L2, 0) -> 2 | D2: =sum(E2:L2) -> 1123 | E2: =IFERROR(VLOOKUP(E13,'2026 Ranking'!$D:$F,3,0),0) -> 232 | F2: =IFERROR(VLOOKUP(F13,'2026 Ranking'!$D:$F,3,0),0) -> 388 | G2: =IFERROR(VLOOKUP(G13,'2026 Ranking'!$D:$F,3,0),0) -> 328 | H2: =IFERROR(VLOOKUP(H13,'2026 Ranking'!$D:$F,3,0),0) -> 30 | I2: =IFERROR(VLOOKUP(I13,'2026 Ranking'!$D:$F,3,0),0) -> 65 | J2: =IFERROR(VLOOKUP(J13,'2026 Ranking'!$D:$F,3,0),0) -> 0 | K2: =IFERROR(VLOOKUP(K13,'2026 Ranking'!$D:$F,3,0),0) -> 0 | L2: =IFERROR(VLOOKUP(L13,'2026 Ranking'!$D:$F,3,0),0) -> 80
A3: Tim | B3: =rank(D3,D$2:D$10) -> 7 | C3: =countif(E3:L3, 0) -> 4 | D3: =sum(E3:L3) -> 521 | E3: =IFERROR(VLOOKUP(E14,'2026 Ranking'!$D:$F,3,0),0) -> 38 | F3: =IFERROR(VLOOKUP(F14,'2026 Ranking'!$D:$F,3,0),0) -> 0 | G3: =IFERROR(VLOOKUP(G14,'2026 Ranking'!$D:$F,3,0),0) -> 0 | H3: =IFERROR(VLOOKUP(H14,'2026 Ranking'!$D:$F,3,0),0) -> 0 | I3: =IFERROR(VLOOKUP(I14,'2026 Ranking'!$D:$F,3,0),0) -> 13 | J3: =IFERROR(VLOOKUP(J14,'2026 Ranking'!$D:$F,3,0),0) -> 454 | K3: =IFERROR(VLOOKUP(K14,'2026 Ranking'!$D:$F,3,0),0) -> 0 | L3: =IFERROR(VLOOKUP(L14,'2026 Ranking'!$D:$F,3,0),0) -> 16
A4: Cameron | B4: =rank(D4,D$2:D$10) -> 4 | C4: =countif(E4:L4, 0) -> 0 | D4: =sum(E4:L4) -> 1285 | E4: =IFERROR(VLOOKUP(E15,'2026 Ranking'!$D:$F,3,0),0) -> 141 | F4: =IFERROR(VLOOKUP(F15,'2026 Ranking'!$D:$F,3,0),0) -> 411 | G4: =IFERROR(VLOOKUP(G15,'2026 Ranking'!$D:$F,3,0),0) -> 248 | H4: =IFERROR(VLOOKUP(H15,'2026 Ranking'!$D:$F,3,0),0) -> 125 | I4: =IFERROR(VLOOKUP(I15,'2026 Ranking'!$D:$F,3,0),0) -> 130 | J4: =IFERROR(VLOOKUP(J15,'2026 Ranking'!$D:$F,3,0),0) -> 119 | K4: =IFERROR(VLOOKUP(K15,'2026 Ranking'!$D:$F,3,0),0) -> 87 | L4: =IFERROR(VLOOKUP(L15,'2026 Ranking'!$D:$F,3,0),0) -> 24
A5: Campbell | B5: =rank(D5,D$2:D$10) -> 3 | C5: =countif(E5:L5, 0) -> 0 | D5: =sum(E5:L5) -> 1426 | E5: =IFERROR(VLOOKUP(E16,'2026 Ranking'!$D:$F,3,0),0) -> 59 | F5: =IFERROR(VLOOKUP(F16,'2026 Ranking'!$D:$F,3,0),0) -> 90 | G5: =IFERROR(VLOOKUP(G16,'2026 Ranking'!$D:$F,3,0),0) -> 302 | H5: =IFERROR(VLOOKUP(H16,'2026 Ranking'!$D:$F,3,0),0) -> 523 | I5: =IFERROR(VLOOKUP(I16,'2026 Ranking'!$D:$F,3,0),0) -> 9 | J5: =IFERROR(VLOOKUP(J16,'2026 Ranking'!$D:$F,3,0),0) -> 335 | K5: =IFERROR(VLOOKUP(K16,'2026 Ranking'!$D:$F,3,0),0) -> 98 | L5: =IFERROR(VLOOKUP(L16,'2026 Ranking'!$D:$F,3,0),0) -> 10
A6: Dave | B6: =rank(D6,D$2:D$10) -> 1 | C6: =countif(E6:L6, 0) -> 1 | D6: =sum(E6:L6) -> 2004 | E6: =IFERROR(VLOOKUP(E17,'2026 Ranking'!$D:$F,3,0),0) -> 261 | F6: =IFERROR(VLOOKUP(F17,'2026 Ranking'!$D:$F,3,0),0) -> 134 | G6: =IFERROR(VLOOKUP(G17,'2026 Ranking'!$D:$F,3,0),0) -> 148 | H6: =IFERROR(VLOOKUP(H17,'2026 Ranking'!$D:$F,3,0),0) -> 852 | I6: =IFERROR(VLOOKUP(I17,'2026 Ranking'!$D:$F,3,0),0) -> 335 | J6: =IFERROR(VLOOKUP(J17,'2026 Ranking'!$D:$F,3,0),0) -> 0 | K6: =IFERROR(VLOOKUP(K17,'2026 Ranking'!$D:$F,3,0),0) -> 204 | L6: =IFERROR(VLOOKUP(L17,'2026 Ranking'!$D:$F,3,0),0) -> 70
A7: Mike | B7: =rank(D7,D$2:D$10) -> 5 | C7: =countif(E7:L7, 0) -> 1 | D7: =sum(E7:L7) -> 1208 | E7: =IFERROR(VLOOKUP(E18,'2026 Ranking'!$D:$F,3,0),0) -> 87 | F7: =IFERROR(VLOOKUP(F18,'2026 Ranking'!$D:$F,3,0),0) -> 45 | G7: =IFERROR(VLOOKUP(G18,'2026 Ranking'!$D:$F,3,0),0) -> 171 | H7: =IFERROR(VLOOKUP(H18,'2026 Ranking'!$D:$F,3,0),0) -> 330 | I7: =IFERROR(VLOOKUP(I18,'2026 Ranking'!$D:$F,3,0),0) -> 33 | J7: =IFERROR(VLOOKUP(J18,'2026 Ranking'!$D:$F,3,0),0) -> 0 | K7: =IFERROR(VLOOKUP(K18,'2026 Ranking'!$D:$F,3,0),0) -> 434 | L7: =IFERROR(VLOOKUP(L18,'2026 Ranking'!$D:$F,3,0),0) -> 108
A8: Andy | B8: =rank(D8,D$2:D$10) -> 2 | C8: =countif(E8:L8, 0) -> 1 | D8: =sum(E8:L8) -> 1959 | E8: =IFERROR(VLOOKUP(E19,'2026 Ranking'!$D:$F,3,0),0) -> 520 | F8: =IFERROR(VLOOKUP(F19,'2026 Ranking'!$D:$F,3,0),0) -> 360 | G8: =IFERROR(VLOOKUP(G19,'2026 Ranking'!$D:$F,3,0),0) -> 116 | H8: =IFERROR(VLOOKUP(H19,'2026 Ranking'!$D:$F,3,0),0) -> 237 | I8: =IFERROR(VLOOKUP(I19,'2026 Ranking'!$D:$F,3,0),0) -> 386 | J8: =IFERROR(VLOOKUP(J19,'2026 Ranking'!$D:$F,3,0),0) -> 84 | K8: =IFERROR(VLOOKUP(K19,'2026 Ranking'!$D:$F,3,0),0) -> 256 | L8: =IFERROR(VLOOKUP(L19,'2026 Ranking'!$D:$F,3,0),0) -> 0
A9: Joe | B9: =rank(D9,D$2:D$10) -> 9 | C9: =countif(E9:L9, 0) -> 2 | D9: =sum(E9:L9) -> 397 | E9: =IFERROR(VLOOKUP(E20,'2026 Ranking'!$D:$F,3,0),0) -> 0 | F9: =IFERROR(VLOOKUP(F20,'2026 Ranking'!$D:$F,3,0),0) -> 0 | G9: =IFERROR(VLOOKUP(G20,'2026 Ranking'!$D:$F,3,0),0) -> 5 | H9: =IFERROR(VLOOKUP(H20,'2026 Ranking'!$D:$F,3,0),0) -> 36 | I9: =IFERROR(VLOOKUP(I20,'2026 Ranking'!$D:$F,3,0),0) -> 58 | J9: =IFERROR(VLOOKUP(J20,'2026 Ranking'!$D:$F,3,0),0) -> 52 | K9: =IFERROR(VLOOKUP(K20,'2026 Ranking'!$D:$F,3,0),0) -> 21 | L9: =IFERROR(VLOOKUP(L20,'2026 Ranking'!$D:$F,3,0),0) -> 225
A10: Geminiani's Hipsters | B10: =rank(D10,D$2:D$10) -> 8 | C10: =countif(E10:L10, 0) -> 2 | D10: =sum(E10:L10) -> 422 | E10: =IFERROR(VLOOKUP(E21,'2026 Ranking'!$D:$F,3,0),0) -> 0 | F10: =IFERROR(VLOOKUP(F21,'2026 Ranking'!$D:$F,3,0),0) -> 100 | G10: =IFERROR(VLOOKUP(G21,'2026 Ranking'!$D:$F,3,0),0) -> 185 | H10: =IFERROR(VLOOKUP(H21,'2026 Ranking'!$D:$F,3,0),0) -> 53 | I10: =IFERROR(VLOOKUP(I21,'2026 Ranking'!$D:$F,3,0),0) -> 0 | J10: =IFERROR(VLOOKUP(J21,'2026 Ranking'!$D:$F,3,0),0) -> 40 | K10: =IFERROR(VLOOKUP(K21,'2026 Ranking'!$D:$F,3,0),0) -> 21 | L10: =IFERROR(VLOOKUP(L21,'2026 Ranking'!$D:$F,3,0),0) -> 23
D12: Manager | E12: 1 | F12: 2 | G12: 3 | H12: 4 | I12: 5 | J12: 6 | K12: 7 | L12: 8
A13: =D13 -> Nick | D13: Nick | E13: AYUSO Juan | F13: VINGEGAARD Jonas | G13: VINE Jay | H13: NARVÁEZ Jhonatan | I13: TARLING Joshua | J13: WILLIAMS Stephen | K13: FORTUNATO Lorenzo | L13: O'CONNOR Ben
A14: =D14 -> Tim | D14: Tim | E14: PHILIPSEN Jasper | F14: KOOIJ Olav | G14: MERLIER Tim | H14: PEDERSEN Mads | I14: STRONG Corbin | J14: CHRISTEN Jan | K14: BLACKMORE Joseph | L14: HINDLEY Jai
A15: =D15 -> Cameron | D15: Cameron | E15: HEALY Ben | F15: JORGENSON Matteo | G15: PIDCOCK Thomas | H15: ONLEY Oscar | I15: ROGLIČ Primož | J15: ARENSMAN Thymen | K15: GANNA Filippo | L15: ALAPHILIPPE Julian
A16: =D16 -> Campbell | D16: Campbell | E16: VAN AERT Wout | F16: LIPOWITZ Florian | G16: MILAN Jonathan | H16: SCARONI Christian | I16: WRIGHT Fred | J16: PELLIZZARI Giulio | K16: STORER Michael | L16: DEL GROSSO Tibor
A17: =D17 -> Dave | D17: Dave | E17: VAUQUELIN Kévin | F17: CICCONE Giulio | G17: GALL Felix | H17: DEL TORO Isaac | I17: MARTINEZ Lenny | J17: POWLESS Neilson | K17: GIRMAY Biniam | L17: JEANNIÈRE Emilien
A18: =D18 -> Mike | D18: Mike | E18: DE LIE Arnaud | F18: SKJELMOSE Mattias | G18: MAGNIER Paul | H18: VAN DER POEL Mathieu | I18: CARAPAZ Richard | J18: NYS Thibau | K18: SEIXAS Paul | L18: GEE-WEST Derek
A19: =D19 -> Andy | D19: Andy | E19: EVENEPOEL Remco | F19: BRENNAN Matthew | G19: MCNULTY Brandon | H19: ALMEIDA João | I19: GRÉGOIRE Romain | J19: MOSCHETTI Matteo | K19: YATES Adam | L19: UIJTDEBROEKS Cian
A20: =D20 -> Joe | D20: Joe | E20: PIDCOCK Joseph | F20: CRAPS Lars | G20: JAKOBSEN Fabio | H20: SÖDERQVIST Jakob | I20: WIDAR Jarno | J20: HIRSCHI Marc | K20: WANG Gustav | L20: POGAČAR Tadej
A21: =D21 -> Geminiani's Hipsters | D21: Geminiani's Hipsters | E21: BISIAUX Léo | F21: NORDHAGEN Jørgen | G21: LAMPERTI Luke | H21: AUGUST Andrew | I21: AGOSTINACCHIO Filippo | J21: FINN Lorenzo | K21: TULETT Ben | L21: ABRAHAMSEN Jonas

Sheet 2026 Ranking
A1: Rank | B1: Prev. Rank | C1: Rank Diff. | D1: Rider | E1: Team | F1: Points | I1: Manager
A2: 1 | B2: 2 | C2: ▲1 | D2: DEL TORO Isaac | E2: UAE Team Emirates - XRG | F2: 852 | I2: {=INDEX('2026 Points'!$D$13:$D$21,MATCH(1,MMULT(--('2026 Points'!$E$13:$L$21=D2),TRANSPOSE(COLUMN('2026 Points'!$E$13:$L$21)^0)),0))} -> Dave
A3: 2 | B3: 65 | C3: ▲63 | D3: SCHMID Mauro | E3: Team Jayco AlUla | F3: 540 | I3: {=INDEX('2026 Points'!$D$13:$D$21,MATCH(1,MMULT(--('2026 Points'!$E$13:$L$21=D3),TRANSPOSE(COLUMN('2026 Points'!$E$13:$L$21)^0)),0))} -> #N/A
A4: 3 | B4: 40 | C4: ▲37 | D4: ANDRESEN Tobias Lund | E4: Decathlon CMA CGM Team | F4: 525 | I4: {=INDEX('2026 Points'!$D$13:$D$21,MATCH(1,MMULT(--('2026 Points'!$E$13:$L$21=D4),TRANSPOSE(COLUMN('2026 Points'!$E$13:$L$21)^0)),0))} -> #N/A
A5: 4 | B5: 14 | C5: ▲10 | D5: SCARONI Christian | E5: XDS Astana Team | F5: 523 | I5: {=INDEX('2026 Points'!$D$13:$D$21,MATCH(1,MMULT(--('2026 Points'!$E$13:$L$21=D5),TRANSPOSE(COLUMN('2026 Points'!$E$13:$L$21)^0)),0))} -> Campbell
A6: 5 | B6: 6 | C6: ▲1 | D6: EVENEPOEL Remco | E6: Red Bull - BORA - hansgrohe | F6: 520 | I6: {=INDEX('2026 Points'!$D$13:$D$21,MATCH(1,MMULT(--('2026 Points'!$E$13:$L$21=D6),TRANSPOSE(COLUMN('2026 Points'!$E$13:$L$21)^0)),0))} -> Andy
A7: 6 | B7: 78 | C7: ▲72 | D7: TIBERI Antonio | E7: Bahrain - Victorious | F7: 465 | I7: {=INDEX('2026 Points'!$D$13:$D$21,MATCH(1,MMULT(--('2026 Points'!$E$13:$L$21=D7),TRANSPOSE(COLUMN('2026 Points'!$E$13:$L$21)^0)),0))} -> #N/A
A8: 7 | B8: 49 | C8: ▲42 | D8: CHRISTEN Jan | E8: UAE Team Emirates - XRG | F8: 454 | I8: {=INDEX('2026 Points'!$D$13:$D$21,MATCH(1,MMULT(--('2026 Points'!$E$13:$L$21=D8),TRANSPOSE(COLUMN('2026 Points'!$E$13:$L$21)^0)),0))} -> Tim
A9: 8 | B9: 99 | C9: ▲91 | D9: SEIXAS Paul | E9: Decathlon CMA CGM Team | F9: 434 | I9: {=INDEX('2026 Points'!$D$13:$D$21,MATCH(1,MMULT(--('2026 Points'!$E$13:$L$21=D9),TRANSPOSE(COLUMN('2026 Points'!$E$13:$L$21)^0)),0))} -> Mike
A10: 9 | B10: 26 | C10: ▲17 | D10: JORGENSON Matteo | E10: Team Visma | Lease a Bike | F10: 411 | I10: {=INDEX('2026 Points'!$D$13:$D$21,MATCH(1,MMULT(--('2026 Points'!$E$13:$L$21=D10),TRANSPOSE(COLUMN('2026 Points'!$E$13:$L$21)^0)),0))} -> Cameron
A11: 10 | B11: 3 | C11: ▼7 | D11: VINGEGAARD Jonas | E11: Team Visma | Lease a Bike | F11: 388 | I11: {=INDEX('2026 Points'!$D$13:$D$21,MATCH(1,MMULT(--('2026 Points'!$E$13:$L$21=D11),TRANSPOSE(COLUMN('2026 Points'!$E$13:$L$21)^0)),0))} -> Nick
A12: 11 | B12: 28 | C12: ▲17 | D12: GRÉGOIRE Romain | E12: Groupama - FDJ United | F12: 386 | I12: {=INDEX('2026 Points'!$D$13:$D$21,MATCH(1,MMULT(--('2026 Points'!$E$13:$L$21=D12),TRANSPOSE(COLUMN('2026 Points'!$E$13:$L$21)^0)),0))} -> Andy
A13: 12 | B13: 89 | C13: ▲77 | D13: MORGADO António | E13: UAE Team Emirates - XRG | F13: 380 | I13: {=INDEX('2026 Points'!$D$13:$D$21,MATCH(1,MMULT(--('2026 Points'!$E$13:$L$21=D13),TRANSPOSE(COLUMN('2026 Points'!$E$13:$L$21)^0)),0))} -> #N/A
... A144: 143 | B144: 548 | C144: ▲405 | D144: GUALDI Simone | E144: Lotto Intermarché | F144: 77 | I144: {=INDEX('2026 Points'!$D$13:$D$21,MATCH(1,MMULT(--('2026 Points'!$E$13:$L$21=D144),TRANSPOSE(COLUMN('2026 Points'!$E$13:$L$21)^0)),0))} -> #N/A
A145: 144 | C145: ▲new | D145: POULARD Athit | E145: Roojai Insurance Winspace | F145: 76 | I145: {=INDEX('2026 Points'!$D$13:$D$21,MATCH(1,MMULT(--('2026 Points'!$E$13:$L$21=D145),TRANSPOSE(COLUMN('2026 Points'!$E$13:$L$21)^0)),0))} -> #N/A
A146: 145 | B146: 488 | C146: ▲343 | D146: POLITT Nils | E146: UAE Team Emirates - XRG | F146: 76 | I146: {=INDEX('2026 Points'!$D$13:$D$21,MATCH(1,MMULT(--('2026 Points'!$E$13:$L$21=D146),TRANSPOSE(COLUMN('2026 Points'!$E$13:$L$21)^0)),0))} -> #N/A
A147: 146 | B147: 243 | C147: ▲97 | D147: HARPER Chris | E147: Pinarello Q36.5 Pro Cycling Team | F147: 75 | I147: {=INDEX('2026 Points'!$D$13:$D$21,MATCH(1,MMULT(--('2026 Points'!$E$13:$L$21=D147),TRANSPOSE(COLUMN('2026 Points'!$E$13:$L$21)^0)),0))} -> #N/A
A148: 147 | B148: 434 | C148: ▲287 | D148: HATHERLY Alan | E148: Team Jayco AlUla | F148: 75 | I148: {=INDEX('2026 Points'!$D$13:$D$21,MATCH(1,MMULT(--('2026 Points'!$E$13:$L$21=D148),TRANSPOSE(COLUMN('2026 Points'!$E$13:$L$21)^0)),0))} -> #N/A
A149: 148 | B149: 115 | C149: ▼33 | D149: DOUBLE Paul | E149: Team Jayco AlUla | F149: 74 | I149: {=INDEX('2026 Points'!$D$13:$D$21,MATCH(1,MMULT(--('2026 Points'!$E$13:$L$21=D149),TRANSPOSE(COLUMN('2026 Points'!$E$13:$L$21)^0)),0))} -> #N/A
A150: 149 | B150: 430 | C150: ▲281 | D150: KOERDT Bjorn | E150: Team Picnic PostNL | F150: 73 | I150: {=INDEX('2026 Points'!$D$13:$D$21,MATCH(1,MMULT(--('2026 Points'!$E$13:$L$21=D150),TRANSPOSE(COLUMN('2026 Points'!$E$13:$L$21)^0)),0))} -> #N/A
A151: 150 | B151: 79 | C151: ▼71 | D151: GATE Aaron | E151: XDS Astana Team | F151: 72 | I151: {=INDEX('2026 Points'!$D$13:$D$21,MATCH(1,MMULT(--('2026 Points'!$E$13:$L$21=D151),TRANSPOSE(COLUMN('2026 Points'!$E$13:$L$21)^0)),0))} -> #N/A
A152: 151 | B152: 328 | C152: ▲177 | D152: ZANONCELLO Enrico | E152: Bardiani CSF 7 Saber | F152: 72 | I152: {=INDEX('2026 Points'!$D$13:$D$21,MATCH(1,MMULT(--('2026 Points'!$E$13:$L$21=D152),TRANSPOSE(COLUMN('2026 Points'!$E$13:$L$21)^0)),0))} -> #N/A
A153: 152 | B153: 1023 | C153: ▲871 | D153: LAU Wan Yau Vincent | E153: Roojai Insurance Winspace | F153: 72 | I153: {=INDEX('2026 Points'!$D$13:$D$21,MATCH(1,MMULT(--('2026 Points'!$E$13:$L$21=D153),TRANSPOSE(COLUMN('2026 Points'!$E$13:$L$21)^0)),0))} -> #N/A
A154: 153 | B154: 185 | C154: ▲32 | D154: PLUIMERS Rick | E154: Tudor Pro Cycling Team | F154: 71 | I154: {=INDEX('2026 Points'!$D$13:$D$21,MATCH(1,MMULT(--('2026 Points'!$E$13:$L$21=D154),TRANSPOSE(COLUMN('2026 Points'!$E$13:$L$21)^0)),0))} -> #N/A
A155: 154 | B155: 108 | C155: ▼46 | D155: TEUNISSEN Mike | E155: XDS Astana Team | F155: 71 | I155: {=INDEX('2026 Points'!$D$13:$D$21,MATCH(1,MMULT(--('2026 Points'!$E$13:$L$21=D155),TRANSPOSE(COLUMN('2026 Points'!$E$13:$L$21)^0)),0))} -> #N/A
A156: 155 | B156: 507 | C156: ▲352 | D156: VERRE Alessandro | E156: MBH Bank CSB Telecom Fort | F156: 71 | I156: {=INDEX('2026 Points'!$D$13:$D$21,MATCH(1,MMULT(--('2026 Points'!$E$13:$L$21=D156),TRANSPOSE(COLUMN('2026 Points'!$E$13:$L$21)^0)),0))} -> #N/A
A157: 156 | C157: ▲new | D157: BEISEMBAY Mansur | E157: XDS Astana Development Team | F157: 71 | I157: {=INDEX('2026 Points'!$D$13:$D$21,MATCH(1,MMULT(--('2026 Points'!$E$13:$L$21=D157),TRANSPOSE(COLUMN('2026 Points'!$E$13:$L$21)^0)),0))} -> #N/A
A158: 157 | B158: 163 | C158: ▲6 | D158: HERMANS Quinten | E158: Pinarello Q36.5 Pro Cycling Team | F158: 71 | I158: {=INDEX('2026 Points'!$D$13:$D$21,MATCH(1,MMULT(--('2026 Points'!$E$13:$L$21=D158),TRANSPOSE(COLUMN('2026 Points'!$E$13:$L$21)^0)),0))} -> #N/A
A159: 158 | B159: 149 | C159: ▼9 | D159: CASTRILLO Pablo | E159: Movistar Team | F159: 70 | I159: {=INDEX('2026 Points'!$D$13:$D$21,MATCH(1,MMULT(--('2026 Points'!$E$13:$L$21=D159),TRANSPOSE(COLUMN('2026 Points'!$E$13:$L$21)^0)),0))} -> #N/A
A160: 159 | B160: 646 | C160: ▲487 | D160: GUDMESTAD Tord | E160: Decathlon CMA CGM Team | F160: 70 | I160: {=INDEX('2026 Points'!$D$13:$D$21,MATCH(1,MMULT(--('2026 Points'!$E$13:$L$21=D160),TRANSPOSE(COLUMN('2026 Points'!$E$13:$L$21)^0)),0))} -> #N/A
A161: 160 | B161: 37 | C161: ▼123 | D161: JEANNIÈRE Emilien | E161: TotalEnergies | F161: 70 | I161: {=INDEX('2026 Points'!$D$13:$D$21,MATCH(1,MMULT(--('2026 Points'!$E$13:$L$21=D161),TRANSPOSE(COLUMN('2026 Points'!$E$13:$L$21)^0)),0))} -> Dave
A162: 161 | B162: 562 | C162: ▲401 | D162: MUNTON Byron | E162: Modern Adventure Pro Cycling | F162: 70 | I162: {=INDEX('2026 Points'!$D$13:$D$21,MATCH(1,MMULT(--('2026 Points'!$E$13:$L$21=D162),TRANSPOSE(COLUMN('2026 Points'!$E$13:$L$21)^0)),0))} -> #N/A
A163: 162 | B163: 498 | C163: ▲336 | D163: GOVEKAR Matevž | E163: Bahrain - Victorious | F163: 70 | I163: {=INDEX('2026 Points'!$D$13:$D$21,MATCH(1,MMULT(--('2026 Points'!$E$13:$L$21=D163),TRANSPOSE(COLUMN('2026 Points'!$E$13:$L$21)^0)),0))} -> #N/A
A164: 163 | B164: 635 | C164: ▲472 | D164: BERWICK Sebastian | E164: Caja Rural - Seguros RGA | F164: 69 | I164: {=INDEX('2026 Points'!$D$13:$D$21,MATCH(1,MMULT(--('2026 Points'!$E$13:$L$21=D164),TRANSPOSE(COLUMN('2026 Points'!$E$13:$L$21)^0)),0))} -> #N/A
A165: 164 | B165: 71 | C165: ▼93 | D165: VAN WILDER Ilan | E165: Soudal Quick-Step | F165: 69 | I165: {=INDEX('2026 Points'!$D$13:$D$21,MATCH(1,MMULT(--('2026 Points'!$E$13:$L$21=D165),TRANSPOSE(COLUMN('2026 Points'!$E$13:$L$21)^0)),0))} -> #N/A
A166: 165 | B166: 207 | C166: ▲42 | D166: MIQUEL Pau | E166: Bahrain - Victorious | F166: 68 | I166: {=INDEX('2026 Points'!$D$13:$D$21,MATCH(1,MMULT(--('2026 Points'!$E$13:$L$21=D166),TRANSPOSE(COLUMN('2026 Points'!$E$13:$L$21)^0)),0))} -> #N/A
A167: 166 | B167: 704 | C167: ▲538 | D167: GLIVAR Gal | E167: Alpecin-Premier Tech | F167: 68 | I167: {=INDEX('2026 Points'!$D$13:$D$21,MATCH(1,MMULT(--('2026 Points'!$E$13:$L$21=D167),TRANSPOSE(COLUMN('2026 Points'!$E$13:$L$21)^0)),0))} -> #N/A
A168: 167 | B168: 139 | C168: ▼28 | D168: TURNER Ben | E168: INEOS Grenadiers | F168: 68 | I168: {=INDEX('2026 Points'!$D$13:$D$21,MATCH(1,MMULT(--('2026 Points'!$E$13:$L$21=D168),TRANSPOSE(COLUMN('2026 Points'!$E$13:$L$21)^0)),0))} -> #N/A
A169: 168 | B169: 1529 | C169: ▲1361 | D169: GRISEL Matys | E169: Lotto Intermarché | F169: 68 | I169: {=INDEX('2026 Points'!$D$13:$D$21,MATCH(1,MMULT(--('2026 Points'!$E$13:$L$21=D169),TRANSPOSE(COLUMN('2026 Points'!$E$13:$L$21)^0)),0))} -> #N/A
... A240: 239 | B240: 1891 | C240: ▲1652 | D240: MUÑOZ Hodei | E240: Soudal Quick-Step Devo Team | F240: 46 | I240: {=INDEX('2026 Points'!$D$13:$D$21,MATCH(1,MMULT(--('2026 Points'!$E$13:$L$21=D240),TRANSPOSE(COLUMN('2026 Points'!$E$13:$L$21)^0)),0))} -> #N/A
...

Sheet 2026 Draft
A1: Nick | C1: Tim | E1: Cameron | G1: Andrew | I1: Dave | L1: Riders - 2025 Final Ranking Order
A2: Budget remaining | B2: =1000-SUM(B5:B12) -> 3 | C2: Budget remaining | D2: =1000-SUM(D5:D12) -> 14 | E2: Budget remaining | F2: =1000-SUM(F5:F12) -> 35 | G2: Budget remaining | H2: =1000-SUM(H5:H12) -> 25 | I2: Budget remaining | J2: =1000-SUM(J5:J12) -> 5 | L2: POGAČAR Tadej
A3: Spaces remaining | B3: =COUNTBLANK(A5:A12) -> 0 | C3: Spaces remaining | D3: =COUNTBLANK(C5:C12) -> 0 | E3: Spaces remaining | F3: =COUNTBLANK(E5:E12) -> 0 | G3: Spaces remaining | H3: =COUNTBLANK(G5:G12) -> 0 | I3: Spaces remaining | J3: =COUNTBLANK(I5:I12) -> 0 | L3: DEL TORO Isaac
A4: Rider | B4: Spend | C4: Rider | D4: Spend | E4: Rider | F4: Spend | G4: Rider | H4: Spend | I4: Rider | J4: Spend | L4: VINGEGAARD Jonas
A5: AYUSO Juan | B5: 280 | C5: PHILIPSEN Jasper | D5: 230 | E5: HEALY Ben | F5: 150 | G5: EVENEPOEL Remco | H5: 520 | I5: VAUQUELIN Kévin | J5: 160 | L5: ALMEIDA João
A6: VINGEGAARD Jonas | B6: 600 | C6: KOOIJ Olav | D6: 190 | E6: JORGENSON Matteo | F6: 170 | G6: BRENNAN Matthew | H6: 220 | I6: CICCONE Giulio | J6: 120 | L6: PEDERSEN Mads
A7: VINE Jay | B7: 110 | C7: MERLIER Tim | D7: 210 | E7: PIDCOCK Thomas | F7: 250 | G7: MCNULTY Brandon | H7: 30 | I7: GALL Felix | J7: 115 | L7: EVENEPOEL Remco
A8: NARVÁEZ Jhonatan | B8: 1 | C8: PEDERSEN Mads | D8: 340 | E8: ONLEY Oscar | F8: 170 | G8: ALMEIDA João | H8: 88 | I8: DEL TORO Isaac | J8: 475 | L8: PIDCOCK Thomas
A9: TARLING Joshua | B9: 1 | C9: STRONG Corbin | D9: 5 | E9: ROGLIČ Primož | F9: 118 | G9: GRÉGOIRE Romain | H9: 30 | I9: MARTINEZ Lenny | J9: 40 | L9: VAN DER POEL Mathieu
A10: WILLIAMS Stephen | B10: 3 | C10: CHRISTEN Jan | D10: 1 | E10: ARENSMAN Thymen | F10: 55 | G10: MOSCHETTI Matteo | H10: 1 | I10: POWLESS Neilson | J10: 10 | L10: ONLEY Oscar
A11: FORTUNATO Lorenzo | B11: 1 | C11: BLACKMORE Joseph | D11: 5 | E11: GANNA Filippo | F11: 40 | G11: YATES Adam | H11: 66 | I11: GIRMAY Biniam | J11: 50 | L11: DE LIE Arnaud
A12: O'CONNOR Ben | B12: 1 | C12: HINDLEY Jai | D12: 5 | E12: ALAPHILIPPE Julian | F12: 12 | G12: UIJTDEBROEKS Cian | H12: 20 | I12: JEANNIÈRE Emilien | J12: 25 | L12: MAGNIER Paul
A13: Mike | C13: Campbell | E13: Joe | G13: Gemini's Hipsters | L13: AYUSO Juan
A14: Budget remaining | B14: =1000-SUM(B17:B24) -> 50 | C14: Budget remaining | D14: =1000-SUM(D17:D24) -> 49 | E14: Budget remaining | F14: =1000-SUM(F17:F24) -> 1000 | G14: Budget remaining | H14: =1000-SUM(H17:H24) -> 1000 | I14: Budget remaining | J14: =1000-SUM(J17:J24) -> 1000 | L14: CICCONE Giulio
A15: Spaces remaining | B15: =COUNTBLANK(A17:A24) -> 0 | C15: Spaces remaining | D15: =COUNTBLANK(C17:C24) -> 0 | E15: Spaces remaining | F15: =COUNTBLANK(E17:E24) -> 0 | G15: Spaces remaining | H15: =COUNTBLANK(G17:G24) -> 0 | I15: Spaces remaining | J15: =COUNTBLANK(I17:I24) -> 8 | L15: SCARONI Christian
A16: Rider | B16: Spend | C16: Rider | D16: Spend | E16: Rider | F16: Spend | G16: Rider | H16: Spend | I16: Rider | J16: Spend | L16: MCNULTY Brandon
A17: DE LIE Arnaud | B17: 260 | C17: VAN AERT Wout | D17: 210 | E17: PIDCOCK Joseph | G17: BISIAUX Léo | L17: VAUQUELIN Kévin
A18: SKJELMOSE Mattias | B18: 155 | C18: LIPOWITZ Florian | D18: 300 | E18: CRAPS Lars | G18: NORDHAGEN Jørgen | L18: MERLIER Tim
A19: MAGNIER Paul | B19: 120 | C19: MILAN Jonathan | D19: 220 | E19: JAKOBSEN Fabio | G19: LAMPERTI Luke | L19: VAN AERT Wout
A20: VAN DER POEL Mathieu | B20: 260 | C20: SCARONI Christian | D20: 160 | E20: SÖDERQVIST Jakob | G20: AUGUST Andrew | L20: MILAN Jonathan
A21: CARAPAZ Richard | B21: 50 | C21: WRIGHT Fred | D21: 30 | E21: WIDAR Jarno | G21: AGOSTINACCHIO Filippo | L21: PHILIPSEN Jasper
A22: NYS Thibau | B22: 40 | C22: PELLIZZARI Giulio | D22: 15 | E22: HIRSCHI Marc | G22: FINN Lorenzo | L22: VINE Jay
A23: SEIXAS Paul | B23: 50 | C23: STORER Michael | D23: 15 | E23: WANG Gustav | G23: TULETT Ben | L23: HEALY Ben
A24: GEE Derek | B24: 15 | C24: DEL GROSSO Tibor | D24: 1 | E24: POGAČAR Tadej | G24: ABRAHAMSEN Jonas | L24: LIPOWITZ Florian
L25: KOOIJ Olav
A26: Budget remaining | B26: =1000-SUM(B29:B36) -> 1000 | C26: Budget remaining | D26: =1000-SUM(D29:D36) -> 1000 | L26: STORER Michael
A27: Spaces remaining | B27: =COUNTBLANK(A29:A36) -> 8 | C27: Spaces remaining | D27: =COUNTBLANK(C29:C36) -> 8 | L27: JORGENSON Matteo
A28: Rider | B28: Spend | C28: Rider | D28: Spend | L28: GALL Felix
L29: GRÉGOIRE Romain
L30: SKJELMOSE Mattias
L31: BRENNAN Matthew
L32: MARTINEZ Lenny
L33: ROGLIČ Primož
L34: NARVÁEZ Jhonatan
L35: ARENSMAN Thymen
L36: GANNA Filippo
L37: STRONG Corbin
L38: JEANNIÈRE Emilien
L39: YATES Simon
L40: POWLESS Neilson
...

Sheet 2025 Draft
A1: Nick | C1: Tim | E1: Cameron | G1: Chris | I1: Dave | L1: Riders | N1: Tim | O1: Nick | P1: Andy | Q1: Dave
A2: Budget remaining | B2: =1000-SUM(B5:B12) -> 0 | C2: Budget remaining | D2: =1000-SUM(D5:D12) -> 110 | E2: Budget remaining | F2: =1000-SUM(F5:F12) -> 92 | G2: Budget remaining | H2: =1000-SUM(H5:H12) -> 250 | I2: Budget remaining | J2: =1000-SUM(J5:J12) -> 0 | L2: POGAČAR Tadej | N2: Brennan (40) | O2: Lipowitz (24) | P2: Buitrago (1) | Q2: Vauquelin
A3: Spaces remaining | B3: =COUNTBLANK(A5:A12) -> 0 | C3: Spaces remaining | D3: =COUNTBLANK(C5:C12) -> 0 | E3: Spaces remaining | F3: =COUNTBLANK(E5:E12) -> 0 | G3: Spaces remaining | H3: =COUNTBLANK(G5:G12) -> 0 | I3: Spaces remaining | J3: =COUNTBLANK(I5:I12) -> 0 | L3: EVENEPOEL Remco | N3: Magnier (40) | O3: Tim Wellens (1) | P3: Egan Bernal (1)
A4: Rider | B4: Spend | C4: Rider | D4: Spend | E4: Rider | F4: Spend | G4: Rider | H4: Spend | I4: Rider | J4: Spend | L4: PHILIPSEN Jasper
A5: NARVÁEZ Jhonatan | B5: 75 | C5: GIRMAY Biniam | D5: 200 | E5: GAUDU David | F5: 15 | G5: ALMEIDA João | H5: 225 | I5: VAN AERT Wout | J5: 375 | L5: HIRSCHI Marc
A6: VINGEGAARD Jonas | B6: 650 | C6: PHILIPSEN Jasper | D6: 350 | E6: EVENEPOEL Remco | F6: 700 | G6: MERLIER Tim | H6: 110 | I6: VAN DER POEL Mathieu | J6: 490 | L6: VINGEGAARD Jonas
A7: CARAPAZ Richard | B7: 90 | C7: MCNULTY Brandon | D7: 70 | E7: MATTHEWS Michael | F7: 30 | G7: YATES Adam | H7: 50 | I7: POWLESS Neilson | J7: 25 | L7: O'CONNOR Ben
A8: EWAN Caleb | B8: 10 | C8: HIRSCHI Marc | D8: 80 | E8: BARDET Romain | F8: 25 | G8: VLASOV Aleksandr | H8: 55 | I8: GROENEWEGEN Dylan | J8: 30 | L8: GIRMAY Biniam
A9: O'CONNOR Ben | B9: 85 | C9: VAN EETVELT Lennert | D9: 40 | E9: COSNEFROY Benoît | F9: 95 | G9: JORGENSON Matteo | H9: 150 | I9: LANDA Mikel | J9: 30 | L9: VAN DER POEL Mathieu
A10: WILLIAMS Stephen | B10: 15 | C10: VAN GILS Maxim | D10: 90 | E10: ABRAHAMSEN Jonas | F10: 20 | G10: RODRÍGUEZ Carlos | H10: 50 | I10: KÜNG Stefan | J10: 10 | L10: ROGLIČ Primož
A11: PIDCOCK Thomas | B11: 40 | C11: GANNA Filippo | D11: 40 | E11: SHEFFIELD Magnus | F11: 13 | G11: AYUSO Juan | H11: 90 | I11: MARTINEZ Lenny | J11: 30 | L11: MERLIER Tim
A12: MAS Enric | B12: 35 | C12: ONLEY Oscar | D12: 20 | E12: ARENSMAN Thymen | F12: 10 | G12: YATES Simon | H12: 20 | I12: CICCONE Giulio | J12: 10 | L12: PEDERSEN Mads
A13: Mike | C13: Andy | E13: Campbell | G13: Joe | L13: JORGENSON Matteo
A14: Budget remaining | B14: =1000-SUM(B17:B24) -> 40 | C14: Budget remaining | D14: =1000-SUM(D17:D24) -> 0 | E14: Budget remaining | F14: =1000-SUM(F17:F24) -> 0 | G14: Budget remaining | H14: =1000-SUM(H17:H24) -> 0 | I14: Budget remaining | J14: =1000-SUM(J17:J24) -> 1000 | L14: VAN AERT Wout
A15: Spaces remaining | B15: =COUNTBLANK(A17:A24) -> 0 | C15: Spaces remaining | D15: =COUNTBLANK(C17:C24) -> 0 | E15: Spaces remaining | F15: =COUNTBLANK(E17:E24) -> 7 | G15: Spaces remaining | H15: =COUNTBLANK(G17:G24) -> 7 | I15: Spaces remaining | J15: =COUNTBLANK(I17:I24) -> 8 | L15: DE LIE Arnaud
A16: Rider | B16: Spend | C16: Rider | D16: Spend | E16: Rider | F16: Spend | G16: Rider | H16: Spend | I16: Rider | J16: Spend | L16: MCNULTY Brandon
A17: DE LIE Arnaud | B17: 130 | C17: POGAČAR Tadej | D17: 993 | E17: POGAČAR Tadej | F17: 993 | G17: POGAČAR Tadej | H17: 993 | L17: YATES Adam
A18: PEDERSEN Mads | B18: 235 | C18: PITHIE Laurence | D18: 1 | F18: 1 | H18: 1 | L18: MAS Enric
A19: MILAN Jonathan | B19: 135 | C19: MADOUAS Valentin | D19: 1 | F19: 1 | H19: 1 | L19: MILAN Jonathan
A20: ROGLIČ Primož | B20: 290 | C20: MOHORIČ Matej | D20: 1 | F20: 1 | H20: 1 | L20: RODRÍGUEZ Carlos
A21: SKJELMOSE Mattias | B21: 70 | C21: HINDLEY Jai | D21: 1 | F21: 1 | H21: 1 | L21: AYUSO Juan
A22: NYS Thibau | B22: 50 | C22: GROENEWEGEN Dylan | D22: 1 | F22: 1 | H22: 1 | L22: VLASOV Aleksandr
A23: KOOIJ Olav | B23: 40 | C23: CORT Magnus | D23: 1 | F23: 1 | H23: 1 | L23: VAN GILS Maxim
A24: DEL TORO Isaac | B24: 10 | C24: GEE Derek | D24: 1 | F24: 1 | H24: 1 | L24: SKJELMOSE Mattias
L25: CARAPAZ Richard
A26: Budget remaining | B26: =1000-SUM(B29:B36) -> 1000 | C26: Budget remaining | D26: =1000-SUM(D29:D36) -> 1000 | L26: ULISSI Diego
A27: Spaces remaining | B27: =COUNTBLANK(A29:A36) -> 8 | C27: Spaces remaining | D27: =COUNTBLANK(C29:C36) -> 8 | L27: ALMEIDA João
A28: Rider | B28: Spend | C28: Rider | D28: Spend | L28: LANDA Mikel
L29: VAN EETVELT Lennert
L30: KOOIJ Olav
L31: PIDCOCK Thomas
L32: COSNEFROY Benoît
L33: WELLENS Tim
L34: KRISTOFF Alexander
L35: KÜNG Stefan
L36: WILLIAMS Stephen
L37: ZINGLE Axel
L38: ONLEY Oscar
L39: ALAPHILIPPE Julian
L40: STRONG Corbin
...

Sheet Current 2025 Points
A1: Team | B1: Rank | C1: Null | D1: Total | E1: Pre Transfer | F1: Post Transfer
A2: Nick | B2: =rank(D2,D$2:D$8) -> 4 | C2: =countif(G2:N2, 0) -> 0 | D2: =E2+F2 -> 8352 | E2: 3619 | F2: =sum(G2:N2) -> 4733 | G2: =IFERROR(VLOOKUP(G11,'Current 2025 Ranking'!$D:$K,8,0),0) -> 612 | H2: =IFERROR(VLOOKUP(H11,'Current 2025 Ranking'!$D:$K,8,0),0) -> 1826 | I2: =IFERROR(VLOOKUP(I11,'Current 2025 Ranking'!$D:$K,8,0),0) -> 173 | J2: =IFERROR(VLOOKUP(J11,'Current 2025 Ranking'!$D:$K,8,0),0) -> 557 | K2: =IFERROR(VLOOKUP(K11,'Current 2025 Ranking'!$D:$K,8,0),0) -> 365 | L2: =IFERROR(VLOOKUP(L11,'Current 2025 Ranking'!$D:$K,8,0),0) -> 359 | M2: =IFERROR(VLOOKUP(M11,'Current 2025 Ranking'!$D:$K,8,0),0) -> 813 | N2: =IFERROR(VLOOKUP(N11,'Current 2025 Ranking'!$D:$K,8,0),0) -> 28
A3: Tim | B3: =rank(D3,D$2:D$8) -> 5 | C3: =countif(G3:N3, 0) -> 1 | D3: =E3+F3 -> 8203 | E3: 4074 | F3: =sum(G3:N3) -> 4129 | G3: =IFERROR(VLOOKUP(G12,'Current 2025 Ranking'!$D:$K,8,0),0) -> 399 | H3: =IFERROR(VLOOKUP(H12,'Current 2025 Ranking'!$D:$K,8,0),0) -> 642 | I3: =IFERROR(VLOOKUP(I12,'Current 2025 Ranking'!$D:$K,8,0),0) -> 931 | J3: =IFERROR(VLOOKUP(J12,'Current 2025 Ranking'!$D:$K,8,0),0) -> 388 | K3: =IFERROR(VLOOKUP(K12,'Current 2025 Ranking'!$D:$K,8,0),0) -> 0 | L3: =IFERROR(VLOOKUP(L12,'Current 2025 Ranking'!$D:$K,8,0),0) -> 861 | M3: =IFERROR(VLOOKUP(M12,'Current 2025 Ranking'!$D:$K,8,0),0) -> 168 | N3: =IFERROR(VLOOKUP(N12,'Current 2025 Ranking'!$D:$K,8,0),0) -> 740
A4: Cameron | B4: =rank(D4,D$2:D$8) -> 7 | C4: =countif(G4:N4, 0) -> 2 | D4: =E4+F4 -> 5714 | E4: 2974 | F4: =sum(G4:N4) -> 2740 | G4: =IFERROR(VLOOKUP(G13,'Current 2025 Ranking'!$D:$K,8,0),0) -> 147 | H4: =IFERROR(VLOOKUP(H13,'Current 2025 Ranking'!$D:$K,8,0),0) -> 1196 | I4: =IFERROR(VLOOKUP(I13,'Current 2025 Ranking'!$D:$K,8,0),0) -> 283 | J4: =IFERROR(VLOOKUP(J13,'Current 2025 Ranking'!$D:$K,8,0),0) -> 0 | K4: =IFERROR(VLOOKUP(K13,'Current 2025 Ranking'!$D:$K,8,0),0) -> 0 | L4: =IFERROR(VLOOKUP(L13,'Current 2025 Ranking'!$D:$K,8,0),0) -> 515 | M4: =IFERROR(VLOOKUP(M13,'Current 2025 Ranking'!$D:$K,8,0),0) -> 68 | N4: =IFERROR(VLOOKUP(N13,'Current 2025 Ranking'!$D:$K,8,0),0) -> 531
A5: Chris | B5: =rank(D5,D$2:D$8) -> 3 | C5: =countif(G5:N5, 0) -> 0 | D5: =E5+F5 -> 8357 | E5: 5485 | F5: =sum(G5:N5) -> 2872 | G5: =IFERROR(VLOOKUP(G14,'Current 2025 Ranking'!$D:$K,8,0),0) -> 636 | H5: =IFERROR(VLOOKUP(H14,'Current 2025 Ranking'!$D:$K,8,0),0) -> 476 | I5: =IFERROR(VLOOKUP(I14,'Current 2025 Ranking'!$D:$K,8,0),0) -> 427 | J5: =IFERROR(VLOOKUP(J14,'Current 2025 Ranking'!$D:$K,8,0),0) -> 108 | K5: =IFERROR(VLOOKUP(K14,'Current 2025 Ranking'!$D:$K,8,0),0) -> 494 | L5: =IFERROR(VLOOKUP(L14,'Current 2025 Ranking'!$D:$K,8,0),0) -> 14 | M5: =IFERROR(VLOOKUP(M14,'Current 2025 Ranking'!$D:$K,8,0),0) -> 425 | N5: =IFERROR(VLOOKUP(N14,'Current 2025 Ranking'!$D:$K,8,0),0) -> 292
A6: Dave | B6: =rank(D6,D$2:D$8) -> 6 | C6: =countif(G6:N6, 0) -> 0 | D6: =E6+F6 -> 7864 | E6: 4972 | F6: =sum(G6:N6) -> 2892 | G6: =IFERROR(VLOOKUP(G15,'Current 2025 Ranking'!$D:$K,8,0),0) -> 415 | H6: =IFERROR(VLOOKUP(H15,'Current 2025 Ranking'!$D:$K,8,0),0) -> 508 | I6: =IFERROR(VLOOKUP(I15,'Current 2025 Ranking'!$D:$K,8,0),0) -> 239 | J6: =IFERROR(VLOOKUP(J15,'Current 2025 Ranking'!$D:$K,8,0),0) -> 212 | K6: =IFERROR(VLOOKUP(K15,'Current 2025 Ranking'!$D:$K,8,0),0) -> 137 | L6: =IFERROR(VLOOKUP(L15,'Current 2025 Ranking'!$D:$K,8,0),0) -> 392 | M6: =IFERROR(VLOOKUP(M15,'Current 2025 Ranking'!$D:$K,8,0),0) -> 304 | N6: =IFERROR(VLOOKUP(N15,'Current 2025 Ranking'!$D:$K,8,0),0) -> 685
A7: Mike | B7: =rank(D7,D$2:D$8) -> 1 | C7: =countif(G7:N7, 0) -> 0 | D7: =E7+F7 -> 11586 | E7: 5616 | F7: =sum(G7:N7) -> 5970 | G7: =IFERROR(VLOOKUP(G16,'Current 2025 Ranking'!$D:$K,8,0),0) -> 1415 | H7: =IFERROR(VLOOKUP(H16,'Current 2025 Ranking'!$D:$K,8,0),0) -> 601 | I7: =IFERROR(VLOOKUP(I16,'Current 2025 Ranking'!$D:$K,8,0),0) -> 574 | J7: =IFERROR(VLOOKUP(J16,'Current 2025 Ranking'!$D:$K,8,0),0) -> 501 | K7: =IFERROR(VLOOKUP(K16,'Current 2025 Ranking'!$D:$K,8,0),0) -> 515 | L7: =IFERROR(VLOOKUP(L16,'Current 2025 Ranking'!$D:$K,8,0),0) -> 41 | M7: =IFERROR(VLOOKUP(M16,'Current 2025 Ranking'!$D:$K,8,0),0) -> 554 | N7: =IFERROR(VLOOKUP(N16,'Current 2025 Ranking'!$D:$K,8,0),0) -> 1769
A8: Andy | B8: =rank(D8,D$2:D$8) -> 2 | C8: =countif(G8:N8, 0) -> 1 | D8: =E8+F8 -> 8606 | E8: 4578 | F8: =sum(G8:N8) -> 4028 | G8: =IFERROR(VLOOKUP(G17,'Current 2025 Ranking'!$D:$K,8,0),0) -> 2621 | H8: =IFERROR(VLOOKUP(H17,'Current 2025 Ranking'!$D:$K,8,0),0) -> 37 | I8: =IFERROR(VLOOKUP(I17,'Current 2025 Ranking'!$D:$K,8,0),0) -> 232 | J8: =IFERROR(VLOOKUP(J17,'Current 2025 Ranking'!$D:$K,8,0),0) -> 227 | K8: =IFERROR(VLOOKUP(K17,'Current 2025 Ranking'!$D:$K,8,0),0) -> 450 | L8: =IFERROR(VLOOKUP(L17,'Current 2025 Ranking'!$D:$K,8,0),0) -> 436 | M8: =IFERROR(VLOOKUP(M17,'Current 2025 Ranking'!$D:$K,8,0),0) -> 25 | N8: =IFERROR(VLOOKUP(N17,'Current 2025 Ranking'!$D:$K,8,0),0) -> 0
F10: Manager | G10: 1 | H10: 2 | I10: 3 | J10: 4 | K10: 5 | L10: 6 | M10: 7 | N10: 8
A11: Nick | F11: Nick | G11: NARVÁEZ Jhonatan | H11: VINGEGAARD Jonas | I11: CARAPAZ Richard | J11: LIPOWITZ Florian | K11: O'CONNOR Ben | L11: WELLENS Tim | M11: PIDCOCK Thomas | N11: MAS Enric
A12: Tim | F12: Tim | G12: GIRMAY Biniam | H12: PHILIPSEN Jasper | I12: MCNULTY Brandon | J12: BRENNAN Matthew | K12: VAN EETVELT Lennert | L12: MAGNIER Paul | M12: GANNA Filippo | N12: ONLEY Oscar
A13: Cameron | F13: Cameron | G13: GAUDU David | H13: EVENEPOEL Remco | I13: MATTHEWS Michael | J13: BARDET Romain | K13: COSNEFROY Benoît | L13: ABRAHAMSEN Jonas | M13: SHEFFIELD Magnus | N13: ARENSMAN Thymen
A14: Chris | F14: Chris | G14: ALMEIDA João | H14: MERLIER Tim | I14: YATES Adam | J14: VLASOV Aleksandr | K14: JORGENSON Matteo | L14: RODRÍGUEZ Carlos | M14: AYUSO Juan | N14: YATES Simon
A15: Dave | F15: Dave | G15: VAN AERT Wout | H15: VAN DER POEL Mathieu | I15: POWLESS Neilson | J15: GROENEWEGEN Dylan | K15: LANDA Mikel | L15: VAUQUELIN Kévin | M15: MARTINEZ Lenny | N15: CICCONE Giulio
A16: Mike | F16: Mike | G16: DE LIE Arnaud | H16: PEDERSEN Mads | I16: MILAN Jonathan | J16: ROGLIČ Primož | K16: SKJELMOSE Mattias | L16: NYS Thibau | M16: KOOIJ Olav | N16: DEL TORO Isaac
A17: Andy | F17: Andy | G17: POGAČAR Tadej | H17: PITHIE Laurence | I17: MADOUAS Valentin | J17: BUITRAGO Santiago | K17: HINDLEY Jai | L17: BERNAL Egan | M17: CORT Magnus | N17: GEE Derek

Sheet Current 2025 Ranking
A1: Rank | B1: Prev. Rank | C1: Rank Diff. | D1: Rider | E1: Team | F1: Points | I1: Manager | K1: Adjusted points | L1: In pre-transfer team? | M1: In post-transfer team?
A2: 1 | B2: 1 | C2: - | D2: POGAČAR Tadej | E2: UAE Team Emirates - XRG | F2: 4921 | I2: {=INDEX('Current 2025 Points'!$F$11:$F$77,MATCH(1,MMULT(--('Current 2025 Points'!$G$11:$N$17=D2),TRANSPOSE(COLUMN('Current 2025 Points'!$G$11:$N$17)^0)),0))} -> Andy | K2: =F2-IFERROR(VLOOKUP(D2,'Pre-transfer 2025 Ranking'!$D:$F,3,0),0) -> 2621 | L2: =countif('Pre-transfer 2025 Points'!$E$11:$L$17,D2) -> 1 | M2: =countif('Current 2025 Points'!$G$11:$N$17,D2) -> 1
A3: 2 | B3: 48 | C3: ▲46 | D3: DEL TORO Isaac | E3: UAE Team Emirates - XRG | F3: 2755 | I3: {=INDEX('Current 2025 Points'!$F$11:$F$77,MATCH(1,MMULT(--('Current 2025 Points'!$G$11:$N$17=D3),TRANSPOSE(COLUMN('Current 2025 Points'!$G$11:$N$17)^0)),0))} -> Mike | K3: =F3-IFERROR(VLOOKUP(D3,'Pre-transfer 2025 Ranking'!$D:$F,3,0),0) -> 1769 | L3: =countif('Pre-transfer 2025 Points'!$E$11:$L$17,D3) -> 1 | M3: =countif('Current 2025 Points'!$G$11:$N$17,D3) -> 1
A4: 3 | B4: 5 | C4: ▲2 | D4: VINGEGAARD Jonas | E4: Team Visma | Lease a Bike | F4: 2399 | I4: {=INDEX('Current 2025 Points'!$F$11:$F$77,MATCH(1,MMULT(--('Current 2025 Points'!$G$11:$N$17=D4),TRANSPOSE(COLUMN('Current 2025 Points'!$G$11:$N$17)^0)),0))} -> Nick | K4: =F4-IFERROR(VLOOKUP(D4,'Pre-transfer 2025 Ranking'!$D:$F,3,0),0) -> 1826 | L4: =countif('Pre-transfer 2025 Points'!$E$11:$L$17,D4) -> 1 | M4: =countif('Current 2025 Points'!$G$11:$N$17,D4) -> 1
A5: 4 | B5: 26 | C5: ▲22 | D5: ALMEIDA João | E5: UAE Team Emirates - XRG | F5: 2270 | I5: {=INDEX('Current 2025 Points'!$F$11:$F$77,MATCH(1,MMULT(--('Current 2025 Points'!$G$11:$N$17=D5),TRANSPOSE(COLUMN('Current 2025 Points'!$G$11:$N$17)^0)),0))} -> Chris | K5: =F5-IFERROR(VLOOKUP(D5,'Pre-transfer 2025 Ranking'!$D:$F,3,0),0) -> 636 | L5: =countif('Pre-transfer 2025 Points'!$E$11:$L$17,D5) -> 1 | M5: =countif('Current 2025 Points'!$G$11:$N$17,D5) -> 1
A6: 5 | B6: 11 | C6: ▲6 | D6: PEDERSEN Mads | E6: Lidl - Trek | F6: 2233 | I6: {=INDEX('Current 2025 Points'!$F$11:$F$77,MATCH(1,MMULT(--('Current 2025 Points'!$G$11:$N$17=D6),TRANSPOSE(COLUMN('Current 2025 Points'!$G$11:$N$17)^0)),0))} -> Mike | K6: =F6-IFERROR(VLOOKUP(D6,'Pre-transfer 2025 Ranking'!$D:$F,3,0),0) -> 601 | L6: =countif('Pre-transfer 2025 Points'!$E$11:$L$17,D6) -> 1 | M6: =countif('Current 2025 Points'!$G$11:$N$17,D6) -> 1
A7: 6 | B7: 2 | C7: ▼4 | D7: EVENEPOEL Remco | E7: Soudal Quick-Step | F7: 1924 | I7: {=INDEX('Current 2025 Points'!$F$11:$F$77,MATCH(1,MMULT(--('Current 2025 Points'!$G$11:$N$17=D7),TRANSPOSE(COLUMN('Current 2025 Points'!$G$11:$N$17)^0)),0))} -> Cameron | K7: =F7-IFERROR(VLOOKUP(D7,'Pre-transfer 2025 Ranking'!$D:$F,3,0),0) -> 1196 | L7: =countif('Pre-transfer 2025 Points'!$E$11:$L$17,D7) -> 1 | M7: =countif('Current 2025 Points'!$G$11:$N$17,D7) -> 1
A8: 7 | B8: 30 | C8: ▲23 | D8: PIDCOCK Thomas | E8: Q36.5 Pro Cycling Team | F8: 1855 | I8: {=INDEX('Current 2025 Points'!$F$11:$F$77,MATCH(1,MMULT(--('Current 2025 Points'!$G$11:$N$17=D8),TRANSPOSE(COLUMN('Current 2025 Points'!$G$11:$N$17)^0)),0))} -> Nick | K8: =F8-IFERROR(VLOOKUP(D8,'Pre-transfer 2025 Ranking'!$D:$F,3,0),0) -> 813 | L8: =countif('Pre-transfer 2025 Points'!$E$11:$L$17,D8) -> 1 | M8: =countif('Current 2025 Points'!$G$11:$N$17,D8) -> 1
A9: 8 | B9: 8 | C9: - | D9: VAN DER POEL Mathieu | E9: Alpecin - Deceuninck | F9: 1621 | I9: {=INDEX('Current 2025 Points'!$F$11:$F$77,MATCH(1,MMULT(--('Current 2025 Points'!$G$11:$N$17=D9),TRANSPOSE(COLUMN('Current 2025 Points'!$G$11:$N$17)^0)),0))} -> Dave | K9: =F9-IFERROR(VLOOKUP(D9,'Pre-transfer 2025 Ranking'!$D:$F,3,0),0) -> 508 | L9: =countif('Pre-transfer 2025 Points'!$E$11:$L$17,D9) -> 1 | M9: =countif('Current 2025 Points'!$G$11:$N$17,D9) -> 1
A10: 9 | B10: 37 | C10: ▲28 | D10: ONLEY Oscar | E10: Team Picnic PostNL | F10: 1620 | I10: {=INDEX('Current 2025 Points'!$F$11:$F$77,MATCH(1,MMULT(--('Current 2025 Points'!$G$11:$N$17=D10),TRANSPOSE(COLUMN('Current 2025 Points'!$G$11:$N$17)^0)),0))} -> Tim | K10: =F10-IFERROR(VLOOKUP(D10,'Pre-transfer 2025 Ranking'!$D:$F,3,0),0) -> 740 | L10: =countif('Pre-transfer 2025 Points'!$E$11:$L$17,D10) -> 1 | M10: =countif('Current 2025 Points'!$G$11:$N$17,D10) -> 1
A11: 10 | B11: 14 | C11: ▲4 | D11: DE LIE Arnaud | E11: Lotto | F11: 1615 | I11: {=INDEX('Current 2025 Points'!$F$11:$F$77,MATCH(1,MMULT(--('Current 2025 Points'!$G$11:$N$17=D11),TRANSPOSE(COLUMN('Current 2025 Points'!$G$11:$N$17)^0)),0))} -> Mike | K11: =F11-IFERROR(VLOOKUP(D11,'Pre-transfer 2025 Ranking'!$D:$F,3,0),0) -> 1415 | L11: =countif('Pre-transfer 2025 Points'!$E$11:$L$17,D11) -> 1 | M11: =countif('Current 2025 Points'!$G$11:$N$17,D11) -> 1
A12: 11 | B12: 144 | C12: ▲133 | D12: MAGNIER Paul | E12: Soudal Quick-Step | F12: 1552 | I12: {=INDEX('Current 2025 Points'!$F$11:$F$77,MATCH(1,MMULT(--('Current 2025 Points'!$G$11:$N$17=D12),TRANSPOSE(COLUMN('Current 2025 Points'!$G$11:$N$17)^0)),0))} -> Tim | K12: =F12-IFERROR(VLOOKUP(D12,'Pre-transfer 2025 Ranking'!$D:$F,3,0),0) -> 861 | L12: =countif('Pre-transfer 2025 Points'!$E$11:$L$17,D12) -> 0 | M12: =countif('Current 2025 Points'!$G$11:$N$17,D12) -> 1
A13: 12 | B13: 20 | C13: ▲8 | D13: AYUSO Juan | E13: UAE Team Emirates - XRG | F13: 1414 | I13: {=INDEX('Current 2025 Points'!$F$11:$F$77,MATCH(1,MMULT(--('Current 2025 Points'!$G$11:$N$17=D13),TRANSPOSE(COLUMN('Current 2025 Points'!$G$11:$N$17)^0)),0))} -> Chris | K13: =F13-IFERROR(VLOOKUP(D13,'Pre-transfer 2025 Ranking'!$D:$F,3,0),0) -> 425 | L13: =countif('Pre-transfer 2025 Points'!$E$11:$L$17,D13) -> 1 | M13: =countif('Current 2025 Points'!$G$11:$N$17,D13) -> 1
... A59: 58 | B59: 102 | C59: ▲44 | D59: JOHANNESSEN Tobias Halland | E59: Uno-X Mobility | F59: 737 | I59: {=INDEX('Current 2025 Points'!$F$11:$F$77,MATCH(1,MMULT(--('Current 2025 Points'!$G$11:$N$17=D59),TRANSPOSE(COLUMN('Current 2025 Points'!$G$11:$N$17)^0)),0))} -> #N/A | K59: =F59-IFERROR(VLOOKUP(D59,'Pre-transfer 2025 Ranking'!$D:$F,3,0),0) -> 414 | L59: =countif('Pre-transfer 2025 Points'!$E$11:$L$17,D59) -> 0 | M59: =countif('Current 2025 Points'!$G$11:$N$17,D59) -> 0
A60: 59 | B60: 77 | C60: ▲18 | D60: GEE Derek | F60: 731 | I60: {=INDEX('Current 2025 Points'!$F$11:$F$77,MATCH(1,MMULT(--('Current 2025 Points'!$G$11:$N$17=D60),TRANSPOSE(COLUMN('Current 2025 Points'!$G$11:$N$17)^0)),0))} -> Andy | K60: =F60-IFERROR(VLOOKUP(D60,'Pre-transfer 2025 Ranking'!$D:$F,3,0),0) -> 0 | L60: =countif('Pre-transfer 2025 Points'!$E$11:$L$17,D60) -> 1 | M60: =countif('Current 2025 Points'!$G$11:$N$17,D60) -> 1
A61: 60 | B61: 59 | C61: ▼1 | D61: BUITRAGO Santiago | E61: Bahrain - Victorious | F61: 728 | I61: {=INDEX('Current 2025 Points'!$F$11:$F$77,MATCH(1,MMULT(--('Current 2025 Points'!$G$11:$N$17=D61),TRANSPOSE(COLUMN('Current 2025 Points'!$G$11:$N$17)^0)),0))} -> Andy | K61: =F61-IFERROR(VLOOKUP(D61,'Pre-transfer 2025 Ranking'!$D:$F,3,0),0) -> 227 | L61: =countif('Pre-transfer 2025 Points'!$E$11:$L$17,D61) -> 0 | M61: =countif('Current 2025 Points'!$G$11:$N$17,D61) -> 1
A62: 61 | B62: 95 | C62: ▲34 | D62: HINDLEY Jai | E62: Red Bull - BORA - hansgrohe | F62: 714 | I62: {=INDEX('Current 2025 Points'!$F$11:$F$77,MATCH(1,MMULT(--('Current 2025 Points'!$G$11:$N$17=D62),TRANSPOSE(COLUMN('Current 2025 Points'!$G$11:$N$17)^0)),0))} -> Andy | K62: =F62-IFERROR(VLOOKUP(D62,'Pre-transfer 2025 Ranking'!$D:$F,3,0),0) -> 450 | L62: =countif('Pre-transfer 2025 Points'!$E$11:$L$17,D62) -> 1 | M62: =countif('Current 2025 Points'!$G$11:$N$17,D62) -> 1
A63: 62 | B63: 138 | C63: ▲76 | D63: PELLIZZARI Giulio | E63: Red Bull - BORA - hansgrohe | F63: 714 | I63: {=INDEX('Current 2025 Points'!$F$11:$F$77,MATCH(1,MMULT(--('Current 2025 Points'!$G$11:$N$17=D63),TRANSPOSE(COLUMN('Current 2025 Points'!$G$11:$N$17)^0)),0))} -> #N/A | K63: =F63-IFERROR(VLOOKUP(D63,'Pre-transfer 2025 Ranking'!$D:$F,3,0),0) -> 416 | L63: =countif('Pre-transfer 2025 Points'!$E$11:$L$17,D63) -> 0 | M63: =countif('Current 2025 Points'!$G$11:$N$17,D63) -> 0
A64: 63 | B64: 283 | C64: ▲220 | D64: LÓPEZ Harold Martín | E64: XDS Astana Team | F64: 709 | I64: {=INDEX('Current 2025 Points'!$F$11:$F$77,MATCH(1,MMULT(--('Current 2025 Points'!$G$11:$N$17=D64),TRANSPOSE(COLUMN('Current 2025 Points'!$G$11:$N$17)^0)),0))} -> #N/A | K64: =F64-IFERROR(VLOOKUP(D64,'Pre-transfer 2025 Ranking'!$D:$F,3,0),0) -> 172 | L64: =countif('Pre-transfer 2025 Points'!$E$11:$L$17,D64) -> 0 | M64: =countif('Current 2025 Points'!$G$11:$N$17,D64) -> 0
A65: 64 | B65: 123 | C65: ▲59 | D65: CHAMPOUSSIN Clément | E65: XDS Astana Team | F65: 699 | I65: {=INDEX('Current 2025 Points'!$F$11:$F$77,MATCH(1,MMULT(--('Current 2025 Points'!$G$11:$N$17=D65),TRANSPOSE(COLUMN('Current 2025 Points'!$G$11:$N$17)^0)),0))} -> #N/A | K65: =F65-IFERROR(VLOOKUP(D65,'Pre-transfer 2025 Ranking'!$D:$F,3,0),0) -> 135 | L65: =countif('Pre-transfer 2025 Points'!$E$11:$L$17,D65) -> 0 | M65: =countif('Current 2025 Points'!$G$11:$N$17,D65) -> 0
A66: 65 | B66: 158 | C66: ▲93 | D66: SCHMID Mauro | E66: Team Jayco AlUla | F66: 698 | I66: {=INDEX('Current 2025 Points'!$F$11:$F$77,MATCH(1,MMULT(--('Current 2025 Points'!$G$11:$N$17=D66),TRANSPOSE(COLUMN('Current 2025 Points'!$G$11:$N$17)^0)),0))} -> #N/A | K66: =F66-IFERROR(VLOOKUP(D66,'Pre-transfer 2025 Ranking'!$D:$F,3,0),0) -> 244 | L66: =countif('Pre-transfer 2025 Points'!$E$11:$L$17,D66) -> 0 | M66: =countif('Current 2025 Points'!$G$11:$N$17,D66) -> 0
A67: 66 | B67: 122 | C67: ▲56 | D67: GODON Dorian | E67: Decathlon AG2R La Mondiale Team | F67: 689 | I67: {=INDEX('Current 2025 Points'!$F$11:$F$77,MATCH(1,MMULT(--('Current 2025 Points'!$G$11:$N$17=D67),TRANSPOSE(COLUMN('Current 2025 Points'!$G$11:$N$17)^0)),0))} -> #N/A | K67: =F67-IFERROR(VLOOKUP(D67,'Pre-transfer 2025 Ranking'!$D:$F,3,0),0) -> 457 | L67: =countif('Pre-transfer 2025 Points'!$E$11:$L$17,D67) -> 0 | M67: =countif('Current 2025 Points'!$G$11:$N$17,D67) -> 0
A68: 67 | B68: 1087 | C68: ▲1020 | D68: TULETT Ben | E68: Team Visma | Lease a Bike | F68: 686 | I68: {=INDEX('Current 2025 Points'!$F$11:$F$77,MATCH(1,MMULT(--('Current 2025 Points'!$G$11:$N$17=D68),TRANSPOSE(COLUMN('Current 2025 Points'!$G$11:$N$17)^0)),0))} -> #N/A | K68: =F68-IFERROR(VLOOKUP(D68,'Pre-transfer 2025 Ranking'!$D:$F,3,0),0) -> 238 | L68: =countif('Pre-transfer 2025 Points'!$E$11:$L$17,D68) -> 0 | M68: =countif('Current 2025 Points'!$G$11:$N$17,D68) -> 0
A69: 68 | B69: 68 | C69: - | D69: SIVAKOV Pavel | E69: UAE Team Emirates - XRG | F69: 677 | I69: {=INDEX('Current 2025 Points'!$F$11:$F$77,MATCH(1,MMULT(--('Current 2025 Points'!$G$11:$N$17=D69),TRANSPOSE(COLUMN('Current 2025 Points'!$G$11:$N$17)^0)),0))} -> #N/A | K69: =F69-IFERROR(VLOOKUP(D69,'Pre-transfer 2025 Ranking'!$D:$F,3,0),0) -> 446 | L69: =countif('Pre-transfer 2025 Points'!$E$11:$L$17,D69) -> 0 | M69: =countif('Current 2025 Points'!$G$11:$N$17,D69) -> 0
A70: 69 | B70: 6 | C70: ▼63 | D70: O'CONNOR Ben | E70: Team Jayco AlUla | F70: 675 | I70: {=INDEX('Current 2025 Points'!$F$11:$F$77,MATCH(1,MMULT(--('Current 2025 Points'!$G$11:$N$17=D70),TRANSPOSE(COLUMN('Current 2025 Points'!$G$11:$N$17)^0)),0))} -> Nick | K70: =F70-IFERROR(VLOOKUP(D70,'Pre-transfer 2025 Ranking'!$D:$F,3,0),0) -> 365 | L70: =countif('Pre-transfer 2025 Points'!$E$11:$L$17,D70) -> 1 | M70: =countif('Current 2025 Points'!$G$11:$N$17,D70) -> 1
A71: 70 | B71: 32 | C71: ▼38 | D71: WELLENS Tim | E71: UAE Team Emirates - XRG | F71: 675 | I71: {=INDEX('Current 2025 Points'!$F$11:$F$77,MATCH(1,MMULT(--('Current 2025 Points'!$G$11:$N$17=D71),TRANSPOSE(COLUMN('Current 2025 Points'!$G$11:$N$17)^0)),0))} -> Nick | K71: =F71-IFERROR(VLOOKUP(D71,'Pre-transfer 2025 Ranking'!$D:$F,3,0),0) -> 359 | L71: =countif('Pre-transfer 2025 Points'!$E$11:$L$17,D71) -> 0 | M71: =countif('Current 2025 Points'!$G$11:$N$17,D71) -> 1
A72: 71 | B72: 70 | C72: ▼1 | D72: VAN WILDER Ilan | E72: Soudal Quick-Step | F72: 668 | I72: {=INDEX('Current 2025 Points'!$F$11:$F$77,MATCH(1,MMULT(--('Current 2025 Points'!$G$11:$N$17=D72),TRANSPOSE(COLUMN('Current 2025 Points'!$G$11:$N$17)^0)),0))} -> #N/A | K72: =F72-IFERROR(VLOOKUP(D72,'Pre-transfer 2025 Ranking'!$D:$F,3,0),0) -> 299 | L72: =countif('Pre-transfer 2025 Points'!$E$11:$L$17,D72) -> 0 | M72: =countif('Current 2025 Points'!$G$11:$N$17,D72) -> 0
... A99: 98 | B99: 45 | C99: ▼53 | D99: SKUJIŅŠ Toms | E99: Lidl - Trek | F99: 547 | I99: {=INDEX('Current 2025 Points'!$F$11:$F$77,MATCH(1,MMULT(--('Current 2025 Points'!$G$11:$N$17=D99),TRANSPOSE(COLUMN('Current 2025 Points'!$G$11:$N$17)^0)),0))} -> #N/A | K99: =F99-IFERROR(VLOOKUP(D99,'Pre-transfer 2025 Ranking'!$D:$F,3,0),0) -> 406 | L99: =countif('Pre-transfer 2025 Points'!$E$11:$L$17,D99) -> 0 | M99: =countif('Current 2025 Points'!$G$11:$N$17,D99) -> 0
A100: 99 | C100: ▲new | D100: SEIXAS Paul | E100: Decathlon AG2R La Mondiale Team | F100: 544 | I100: {=INDEX('Current 2025 Points'!$F$11:$F$77,MATCH(1,MMULT(--('Current 2025 Points'!$G$11:$N$17=D100),TRANSPOSE(COLUMN('Current 2025 Points'!$G$11:$N$17)^0)),0))} -> #N/A | K100: =F100-IFERROR(VLOOKUP(D100,'Pre-transfer 2025 Ranking'!$D:$F,3,0),0) -> 279 | L100: =countif('Pre-transfer 2025 Points'!$E$11:$L$17,D100) -> 0 | M100: =countif('Current 2025 Points'!$G$11:$N$17,D100) -> 0
A101: 100 | B101: 111 | C101: ▲11 | D101: PARET-PEINTRE Aurélien | E101: Decathlon AG2R La Mondiale Team | F101: 539 | I101: {=INDEX('Current 2025 Points'!$F$11:$F$77,MATCH(1,MMULT(--('Current 2025 Points'!$G$11:$N$17=D101),TRANSPOSE(COLUMN('Current 2025 Points'!$G$11:$N$17)^0)),0))} -> #N/A | K101: =F101-IFERROR(VLOOKUP(D101,'Pre-transfer 2025 Ranking'!$D:$F,3,0),0) -> 285 | L101: =countif('Pre-transfer 2025 Points'!$E$11:$L$17,D101) -> 0 | M101: =countif('Current 2025 Points'!$G$11:$N$17,D101) -> 0
A102: 101 | B102: 52 | C102: ▼49 | D102: GROENEWEGEN Dylan | E102: Team Jayco AlUla | F102: 538 | I102: {=INDEX('Current 2025 Points'!$F$11:$F$77,MATCH(1,MMULT(--('Current 2025 Points'!$G$11:$N$17=D102),TRANSPOSE(COLUMN('Current 2025 Points'!$G$11:$N$17)^0)),0))} -> Dave | K102: =F102-IFERROR(VLOOKUP(D102,'Pre-transfer 2025 Ranking'!$D:$F,3,0),0) -> 212 | L102: =countif('Pre-transfer 2025 Points'!$E$11:$L$17,D102) -> 2 | M102: =countif('Current 2025 Points'!$G$11:$N$17,D102) -> 1
A103: 102 | B103: 400 | C103: ▲298 | D103: ASKEY Lewis | E103: Groupama - FDJ | F103: 535 | I103: {=INDEX('Current 2025 Points'!$F$11:$F$77,MATCH(1,MMULT(--('Current 2025 Points'!$G$11:$N$17=D103),TRANSPOSE(COLUMN('Current 2025 Points'!$G$11:$N$17)^0)),0))} -> #N/A | K103: =F103-IFERROR(VLOOKUP(D103,'Pre-transfer 2025 Ranking'!$D:$F,3,0),0) -> 39 | L103: =countif('Pre-transfer 2025 Points'!$E$11:$L$17,D103) -> 0 | M103: =countif('Current 2025 Points'!$G$11:$N$17,D103) -> 0
A104: 103 | B104: 143 | C104: ▲40 | D104: SILVA Guillermo Thomas | E104: Caja Rural - Seguros RGA | F104: 531 | I104: {=INDEX('Current 2025 Points'!$F$11:$F$77,MATCH(1,MMULT(--('Current 2025 Points'!$G$11:$N$17=D104),TRANSPOSE(COLUMN('Current 2025 Points'!$G$11:$N$17)^0)),0))} -> #N/A | K104: =F104-IFERROR(VLOOKUP(D104,'Pre-transfer 2025 Ranking'!$D:$F,3,0),0) -> 223 | L104: =countif('Pre-transfer 2025 Points'!$E$11:$L$17,D104) -> 0 | M104: =countif('Current 2025 Points'!$G$11:$N$17,D104) -> 0
A105: 104 | B105: 490 | C105: ▲386 | D105: KULSET Johannes | E105: Uno-X Mobility | F105: 527 | I105: {=INDEX('Current 2025 Points'!$F$11:$F$77,MATCH(1,MMULT(--('Current 2025 Points'!$G$11:$N$17=D105),TRANSPOSE(COLUMN('Current 2025 Points'!$G$11:$N$17)^0)),0))} -> #N/A | K105: =F105-IFERROR(VLOOKUP(D105,'Pre-transfer 2025 Ranking'!$D:$F,3,0),0) -> 247 | L105: =countif('Pre-transfer 2025 Points'!$E$11:$L$17,D105) -> 0 | M105: =countif('Current 2025 Points'!$G$11:$N$17,D105) -> 0
A106: 105 | B106: 128 | C106: ▲23 | D106: KUSS Sepp | E106: Team Visma | Lease a Bike | F106: 527 | I106: {=INDEX('Current 2025 Points'!$F$11:$F$77,MATCH(1,MMULT(--('Current 2025 Points'!$G$11:$N$17=D106),TRANSPOSE(COLUMN('Current 2025 Points'!$G$11:$N$17)^0)),0))} -> #N/A | K106: =F106-IFERROR(VLOOKUP(D106,'Pre-transfer 2025 Ranking'!$D:$F,3,0),0) -> 462 | L106: =countif('Pre-transfer 2025 Points'!$E$11:$L$17,D106) -> 0 | M106: =countif('Current 2025 Points'!$G$11:$N$17,D106) -> 0
A107: 106 | B107: 506 | C107: ▲400 | D107: BAGIOLI Andrea | E107: Lidl - Trek | F107: 524 | I107: {=INDEX('Current 2025 Points'!$F$11:$F$77,MATCH(1,MMULT(--('Current 2025 Points'!$G$11:$N$17=D107),TRANSPOSE(COLUMN('Current 2025 Points'!$G$11:$N$17)^0)),0))} -> #N/A | K107: =F107-IFERROR(VLOOKUP(D107,'Pre-transfer 2025 Ranking'!$D:$F,3,0),0) -> 169 | L107: =countif('Pre-transfer 2025 Points'!$E$11:$L$17,D107) -> 0 | M107: =countif('Current 2025 Points'!$G$11:$N$17,D107) -> 0
A108: 107 | B108: 202 | C108: ▲95 | D108: PLAPP Luke | E108: Team Jayco AlUla | F108: 516 | I108: {=INDEX('Current 2025 Points'!$F$11:$F$77,MATCH(1,MMULT(--('Current 2025 Points'!$G$11:$N$17=D108),TRANSPOSE(COLUMN('Current 2025 Points'!$G$11:$N$17)^0)),0))} -> #N/A | K108: =F108-IFERROR(VLOOKUP(D108,'Pre-transfer 2025 Ranking'!$D:$F,3,0),0) -> 251 | L108: =countif('Pre-transfer 2025 Points'!$E$11:$L$17,D108) -> 0 | M108: =countif('Current 2025 Points'!$G$11:$N$17,D108) -> 0
A109: 108 | B109: 146 | C109: ▲38 | D109: TEUNISSEN Mike | E109: XDS Astana Team | F109: 515 | I109: {=INDEX('Current 2025 Points'!$F$11:$F$77,MATCH(1,MMULT(--('Current 2025 Points'!$G$11:$N$17=D109),TRANSPOSE(COLUMN('Current 2025 Points'!$G$11:$N$17)^0)),0))} -> #N/A | K109: =F109-IFERROR(VLOOKUP(D109,'Pre-transfer 2025 Ranking'!$D:$F,3,0),0) -> 183 | L109: =countif('Pre-transfer 2025 Points'!$E$11:$L$17,D109) -> 0 | M109: =countif('Current 2025 Points'!$G$11:$N$17,D109) -> 0
A110: 109 | B110: 258 | C110: ▲149 | D110: MOSCHETTI Matteo | E110: Q36.5 Pro Cycling Team | F110: 514 | I110: {=INDEX('Current 2025 Points'!$F$11:$F$77,MATCH(1,MMULT(--('Current 2025 Points'!$G$11:$N$17=D110),TRANSPOSE(COLUMN('Current 2025 Points'!$G$11:$N$17)^0)),0))} -> #N/A | K110: =F110-IFERROR(VLOOKUP(D110,'Pre-transfer 2025 Ranking'!$D:$F,3,0),0) -> 93 | L110: =countif('Pre-transfer 2025 Points'!$E$11:$L$17,D110) -> 0 | M110: =countif('Current 2025 Points'!$G$11:$N$17,D110) -> 0
A111: 110 | B111: 61 | C111: ▼49 | D111: TRENTIN Matteo | E111: Tudor Pro Cycling Team | F111: 512 | I111: {=INDEX('Current 2025 Points'!$F$11:$F$77,MATCH(1,MMULT(--('Current 2025 Points'!$G$11:$N$17=D111),TRANSPOSE(COLUMN('Current 2025 Points'!$G$11:$N$17)^0)),0))} -> #N/A | K111: =F111-IFERROR(VLOOKUP(D111,'Pre-transfer 2025 Ranking'!$D:$F,3,0),0) -> 346 | L111: =countif('Pre-transfer 2025 Points'!$E$11:$L$17,D111) -> 0 | M111: =countif('Current 2025 Points'!$G$11:$N$17,D111) -> 0
...

Sheet Pre-transfer 2025 Points
A1: Team | B1: Rank | C1: Null | D1: Points
A2: Nick | B2: =rank(D2,D$2:D$8) -> 6 | C2: =countif(E2:L2, 0) -> 0 | D2: =sum(E2:L2) -> 3619 | E2: =IFERROR(VLOOKUP(E11,'Pre-transfer 2025 Ranking'!$D:$F,3,0),0) -> 389 | F2: =IFERROR(VLOOKUP(F11,'Pre-transfer 2025 Ranking'!$D:$F,3,0),0) -> 573 | G2: =IFERROR(VLOOKUP(G11,'Pre-transfer 2025 Ranking'!$D:$F,3,0),0) -> 612 | H2: =IFERROR(VLOOKUP(H11,'Pre-transfer 2025 Ranking'!$D:$F,3,0),0) -> 70 | I2: =IFERROR(VLOOKUP(I11,'Pre-transfer 2025 Ranking'!$D:$F,3,0),0) -> 310 | J2: =IFERROR(VLOOKUP(J11,'Pre-transfer 2025 Ranking'!$D:$F,3,0),0) -> 10 | K2: =IFERROR(VLOOKUP(K11,'Pre-transfer 2025 Ranking'!$D:$F,3,0),0) -> 1042 | L2: =IFERROR(VLOOKUP(L11,'Pre-transfer 2025 Ranking'!$D:$F,3,0),0) -> 613
A3: Tim | B3: =rank(D3,D$2:D$8) -> 5 | C3: =countif(E3:L3, 0) -> 0 | D3: =sum(E3:L3) -> 4074 | E3: =IFERROR(VLOOKUP(E12,'Pre-transfer 2025 Ranking'!$D:$F,3,0),0) -> 468 | F3: =IFERROR(VLOOKUP(F12,'Pre-transfer 2025 Ranking'!$D:$F,3,0),0) -> 606 | G3: =IFERROR(VLOOKUP(G12,'Pre-transfer 2025 Ranking'!$D:$F,3,0),0) -> 407 | H3: =IFERROR(VLOOKUP(H12,'Pre-transfer 2025 Ranking'!$D:$F,3,0),0) -> 332 | I3: =IFERROR(VLOOKUP(I12,'Pre-transfer 2025 Ranking'!$D:$F,3,0),0) -> 355 | J3: =IFERROR(VLOOKUP(J12,'Pre-transfer 2025 Ranking'!$D:$F,3,0),0) -> 238 | K3: =IFERROR(VLOOKUP(K12,'Pre-transfer 2025 Ranking'!$D:$F,3,0),0) -> 788 | L3: =IFERROR(VLOOKUP(L12,'Pre-transfer 2025 Ranking'!$D:$F,3,0),0) -> 880
A4: Cameron | B4: =rank(D4,D$2:D$8) -> 7 | C4: =countif(E4:L4, 0) -> 0 | D4: =sum(E4:L4) -> 2974 | E4: =IFERROR(VLOOKUP(E13,'Pre-transfer 2025 Ranking'!$D:$F,3,0),0) -> 165 | F4: =IFERROR(VLOOKUP(F13,'Pre-transfer 2025 Ranking'!$D:$F,3,0),0) -> 728 | G4: =IFERROR(VLOOKUP(G13,'Pre-transfer 2025 Ranking'!$D:$F,3,0),0) -> 558 | H4: =IFERROR(VLOOKUP(H13,'Pre-transfer 2025 Ranking'!$D:$F,3,0),0) -> 224 | I4: =IFERROR(VLOOKUP(I13,'Pre-transfer 2025 Ranking'!$D:$F,3,0),0) -> 273 | J4: =IFERROR(VLOOKUP(J13,'Pre-transfer 2025 Ranking'!$D:$F,3,0),0) -> 67 | K4: =IFERROR(VLOOKUP(K13,'Pre-transfer 2025 Ranking'!$D:$F,3,0),0) -> 505 | L4: =IFERROR(VLOOKUP(L13,'Pre-transfer 2025 Ranking'!$D:$F,3,0),0) -> 454
A5: Chris | B5: =rank(D5,D$2:D$8) -> 2 | C5: =countif(E5:L5, 0) -> 0 | D5: =sum(E5:L5) -> 5485 | E5: =IFERROR(VLOOKUP(E14,'Pre-transfer 2025 Ranking'!$D:$F,3,0),0) -> 1634 | F5: =IFERROR(VLOOKUP(F14,'Pre-transfer 2025 Ranking'!$D:$F,3,0),0) -> 799 | G5: =IFERROR(VLOOKUP(G14,'Pre-transfer 2025 Ranking'!$D:$F,3,0),0) -> 419 | H5: =IFERROR(VLOOKUP(H14,'Pre-transfer 2025 Ranking'!$D:$F,3,0),0) -> 102 | I5: =IFERROR(VLOOKUP(I14,'Pre-transfer 2025 Ranking'!$D:$F,3,0),0) -> 633 | J5: =IFERROR(VLOOKUP(J14,'Pre-transfer 2025 Ranking'!$D:$F,3,0),0) -> 273 | K5: =IFERROR(VLOOKUP(K14,'Pre-transfer 2025 Ranking'!$D:$F,3,0),0) -> 989 | L5: =IFERROR(VLOOKUP(L14,'Pre-transfer 2025 Ranking'!$D:$F,3,0),0) -> 636
A6: Dave | B6: =rank(D6,D$2:D$8) -> 3 | C6: =countif(E6:L6, 0) -> 0 | D6: =sum(E6:L6) -> 4972 | E6: =IFERROR(VLOOKUP(E15,'Pre-transfer 2025 Ranking'!$D:$F,3,0),0) -> 859 | F6: =IFERROR(VLOOKUP(F15,'Pre-transfer 2025 Ranking'!$D:$F,3,0),0) -> 1113 | G6: =IFERROR(VLOOKUP(G15,'Pre-transfer 2025 Ranking'!$D:$F,3,0),0) -> 650 | H6: =IFERROR(VLOOKUP(H15,'Pre-transfer 2025 Ranking'!$D:$F,3,0),0) -> 326 | I6: =IFERROR(VLOOKUP(I15,'Pre-transfer 2025 Ranking'!$D:$F,3,0),0) -> 322 | J6: =IFERROR(VLOOKUP(J15,'Pre-transfer 2025 Ranking'!$D:$F,3,0),0) -> 229 | K6: =IFERROR(VLOOKUP(K15,'Pre-transfer 2025 Ranking'!$D:$F,3,0),0) -> 753 | L6: =IFERROR(VLOOKUP(L15,'Pre-transfer 2025 Ranking'!$D:$F,3,0),0) -> 720
A7: Mike | B7: =rank(D7,D$2:D$8) -> 1 | C7: =countif(E7:L7, 0) -> 0 | D7: =sum(E7:L7) -> 5616 | E7: =IFERROR(VLOOKUP(E16,'Pre-transfer 2025 Ranking'!$D:$F,3,0),0) -> 200 | F7: =IFERROR(VLOOKUP(F16,'Pre-transfer 2025 Ranking'!$D:$F,3,0),0) -> 1632 | G7: =IFERROR(VLOOKUP(G16,'Pre-transfer 2025 Ranking'!$D:$F,3,0),0) -> 694 | H7: =IFERROR(VLOOKUP(H16,'Pre-transfer 2025 Ranking'!$D:$F,3,0),0) -> 533 | I7: =IFERROR(VLOOKUP(I16,'Pre-transfer 2025 Ranking'!$D:$F,3,0),0) -> 590 | J7: =IFERROR(VLOOKUP(J16,'Pre-transfer 2025 Ranking'!$D:$F,3,0),0) -> 374 | K7: =IFERROR(VLOOKUP(K16,'Pre-transfer 2025 Ranking'!$D:$F,3,0),0) -> 607 | L7: =IFERROR(VLOOKUP(L16,'Pre-transfer 2025 Ranking'!$D:$F,3,0),0) -> 986
A8: Andy | B8: =rank(D8,D$2:D$8) -> 4 | C8: =countif(E8:L8, 0) -> 0 | D8: =sum(E8:L8) -> 4578 | E8: =IFERROR(VLOOKUP(E17,'Pre-transfer 2025 Ranking'!$D:$F,3,0),0) -> 2300 | F8: =IFERROR(VLOOKUP(F17,'Pre-transfer 2025 Ranking'!$D:$F,3,0),0) -> 197 | G8: =IFERROR(VLOOKUP(G17,'Pre-transfer 2025 Ranking'!$D:$F,3,0),0) -> 177 | H8: =IFERROR(VLOOKUP(H17,'Pre-transfer 2025 Ranking'!$D:$F,3,0),0) -> 126 | I8: =IFERROR(VLOOKUP(I17,'Pre-transfer 2025 Ranking'!$D:$F,3,0),0) -> 264 | J8: =IFERROR(VLOOKUP(J17,'Pre-transfer 2025 Ranking'!$D:$F,3,0),0) -> 326 | K8: =IFERROR(VLOOKUP(K17,'Pre-transfer 2025 Ranking'!$D:$F,3,0),0) -> 457 | L8: =IFERROR(VLOOKUP(L17,'Pre-transfer 2025 Ranking'!$D:$F,3,0),0) -> 731
D10: Manager | E10: 1 | F10: 2 | G10: 3 | H10: 4 | I10: 5 | J10: 6 | K10: 7 | L10: 8
A11: =D11 -> Nick | D11: Nick | E11: NARVÁEZ Jhonatan | F11: VINGEGAARD Jonas | G11: CARAPAZ Richard | H11: EWAN Caleb | I11: O'CONNOR Ben | J11: WILLIAMS Stephen | K11: PIDCOCK Thomas | L11: MAS Enric
A12: =D12 -> Tim | D12: Tim | E12: GIRMAY Biniam | F12: PHILIPSEN Jasper | G12: MCNULTY Brandon | H12: HIRSCHI Marc | I12: VAN EETVELT Lennert | J12: VAN GILS Maxim | K12: GANNA Filippo | L12: ONLEY Oscar
A13: =D13 -> Cameron | D13: Cameron | E13: GAUDU David | F13: EVENEPOEL Remco | G13: MATTHEWS Michael | H13: BARDET Romain | I13: COSNEFROY Benoît | J13: ABRAHAMSEN Jonas | K13: SHEFFIELD Magnus | L13: ARENSMAN Thymen
A14: =D14 -> Chris | D14: Chris | E14: ALMEIDA João | F14: MERLIER Tim | G14: YATES Adam | H14: VLASOV Aleksandr | I14: JORGENSON Matteo | J14: RODRÍGUEZ Carlos | K14: AYUSO Juan | L14: YATES Simon
A15: =D15 -> Dave | D15: Dave | E15: VAN AERT Wout | F15: VAN DER POEL Mathieu | G15: POWLESS Neilson | H15: GROENEWEGEN Dylan | I15: LANDA Mikel | J15: KÜNG Stefan | K15: MARTINEZ Lenny | L15: CICCONE Giulio
A16: =D16 -> Mike | D16: Mike | E16: DE LIE Arnaud | F16: PEDERSEN Mads | G16: MILAN Jonathan | H16: ROGLIČ Primož | I16: SKJELMOSE Mattias | J16: NYS Thibau | K16: KOOIJ Olav | L16: DEL TORO Isaac
A17: =D17 -> Andy | D17: Andy | E17: POGAČAR Tadej | F17: PITHIE Laurence | G17: MADOUAS Valentin | H17: MOHORIČ Matej | I17: HINDLEY Jai | J17: GROENEWEGEN Dylan | K17: CORT Magnus | L17: GEE Derek

Sheet Pre-transfer 2025 Ranking
A1: Rank | B1: Prev. Rank | C1: Rank Diff. | D1: Rider | E1: Team | F1: Points | I1: Manager
A2: 1 | B2: 1 | C2: - | D2: POGAČAR Tadej | E2: UAE Team Emirates - XRG | F2: 2300 | I2: {=INDEX('Pre-transfer 2025 Points'!$D$11:$D$17,MATCH(1,MMULT(--('Pre-transfer 2025 Points'!$E$11:$L$17=D2),TRANSPOSE(COLUMN('Pre-transfer 2025 Points'!$E$11:$L$17)^0)),0))} -> Andy
A3: 2 | B3: 26 | C3: ▲24 | D3: ALMEIDA João | E3: UAE Team Emirates - XRG | F3: 1634 | I3: {=INDEX('Pre-transfer 2025 Points'!$D$11:$D$17,MATCH(1,MMULT(--('Pre-transfer 2025 Points'!$E$11:$L$17=D3),TRANSPOSE(COLUMN('Pre-transfer 2025 Points'!$E$11:$L$17)^0)),0))} -> Chris
A4: 3 | B4: 11 | C4: ▲8 | D4: PEDERSEN Mads | E4: Lidl - Trek | F4: 1632 | I4: {=INDEX('Pre-transfer 2025 Points'!$D$11:$D$17,MATCH(1,MMULT(--('Pre-transfer 2025 Points'!$E$11:$L$17=D4),TRANSPOSE(COLUMN('Pre-transfer 2025 Points'!$E$11:$L$17)^0)),0))} -> Mike
A5: 4 | B5: 8 | C5: ▲4 | D5: VAN DER POEL Mathieu | E5: Alpecin - Deceuninck | F5: 1113 | I5: {=INDEX('Pre-transfer 2025 Points'!$D$11:$D$17,MATCH(1,MMULT(--('Pre-transfer 2025 Points'!$E$11:$L$17=D5),TRANSPOSE(COLUMN('Pre-transfer 2025 Points'!$E$11:$L$17)^0)),0))} -> Dave
A6: 5 | B6: 30 | C6: ▲25 | D6: PIDCOCK Thomas | E6: Q36.5 Pro Cycling Team | F6: 1042 | I6: {=INDEX('Pre-transfer 2025 Points'!$D$11:$D$17,MATCH(1,MMULT(--('Pre-transfer 2025 Points'!$E$11:$L$17=D6),TRANSPOSE(COLUMN('Pre-transfer 2025 Points'!$E$11:$L$17)^0)),0))} -> Nick
A7: 6 | B7: 20 | C7: ▲14 | D7: AYUSO Juan | E7: UAE Team Emirates - XRG | F7: 989 | I7: {=INDEX('Pre-transfer 2025 Points'!$D$11:$D$17,MATCH(1,MMULT(--('Pre-transfer 2025 Points'!$E$11:$L$17=D7),TRANSPOSE(COLUMN('Pre-transfer 2025 Points'!$E$11:$L$17)^0)),0))} -> Chris
A8: 7 | B8: 48 | C8: ▲41 | D8: DEL TORO Isaac | E8: UAE Team Emirates - XRG | F8: 986 | I8: {=INDEX('Pre-transfer 2025 Points'!$D$11:$D$17,MATCH(1,MMULT(--('Pre-transfer 2025 Points'!$E$11:$L$17=D8),TRANSPOSE(COLUMN('Pre-transfer 2025 Points'!$E$11:$L$17)^0)),0))} -> Mike
